Traceback (most recent call last):
  File "/opt/hostedtoolcache/Python/3.10.13/x64/lib/python3.10/site-packages/jupyter_cache/executors/utils.py", line 58, in single_nb_execution
    executenb(
  File "/opt/hostedtoolcache/Python/3.10.13/x64/lib/python3.10/site-packages/nbclient/client.py", line 1314, in execute
    return NotebookClient(nb=nb, resources=resources, km=km, **kwargs).execute()
  File "/opt/hostedtoolcache/Python/3.10.13/x64/lib/python3.10/site-packages/jupyter_core/utils/__init__.py", line 165, in wrapped
    return loop.run_until_complete(inner)
  File "/opt/hostedtoolcache/Python/3.10.13/x64/lib/python3.10/asyncio/base_events.py", line 649, in run_until_complete
    return future.result()
  File "/opt/hostedtoolcache/Python/3.10.13/x64/lib/python3.10/site-packages/nbclient/client.py", line 709, in async_execute
    await self.async_execute_cell(
  File "/opt/hostedtoolcache/Python/3.10.13/x64/lib/python3.10/site-packages/nbclient/client.py", line 1062, in async_execute_cell
    await self._check_raise_for_error(cell, cell_index, exec_reply)
  File "/opt/hostedtoolcache/Python/3.10.13/x64/lib/python3.10/site-packages/nbclient/client.py", line 918, in _check_raise_for_error
    raise CellExecutionError.from_cell_and_msg(cell, exec_reply_content)
nbclient.exceptions.CellExecutionError: An error occurred while executing the following cell:
------------------
df = pd.read_csv(
    "https://github.com/GLAM-Workbench/trove-parliamentary-papers-data/raw/main/trove-parliamentary-papers.csv",
    keep_default_na=False,
)

stats = [
    ["Number of digitised Parliamentary Papers", df.shape[0]],
    [
        "Number of Parliamentary Papers with OCRd text",
        df.loc[df["text_file"].notnull()].shape[0],
    ],
    ["Total number of pages", df["pages"].sum()],
    ["Median number of pages per publication", df["pages"].median()],
]

stats_df = pd.DataFrame(stats)
stats_df.style.format(thousands=",", precision=0).hide().hide(axis=1).set_properties(
    **{"text-align": "left"}
)
------------------


[0;31m---------------------------------------------------------------------------[0m
[0;31mKeyError[0m                                  Traceback (most recent call last)
File [0;32m/opt/hostedtoolcache/Python/3.10.13/x64/lib/python3.10/site-packages/pandas/core/indexes/base.py:3805[0m, in [0;36mIndex.get_loc[0;34m(self, key)[0m
[1;32m   3804[0m [38;5;28;01mtry[39;00m:
[0;32m-> 3805[0m     [38;5;28;01mreturn[39;00m [38;5;28;43mself[39;49m[38;5;241;43m.[39;49m[43m_engine[49m[38;5;241;43m.[39;49m[43mget_loc[49m[43m([49m[43mcasted_key[49m[43m)[49m
[1;32m   3806[0m [38;5;28;01mexcept[39;00m [38;5;167;01mKeyError[39;00m [38;5;28;01mas[39;00m err:

File [0;32mindex.pyx:167[0m, in [0;36mpandas._libs.index.IndexEngine.get_loc[0;34m()[0m

File [0;32mindex.pyx:196[0m, in [0;36mpandas._libs.index.IndexEngine.get_loc[0;34m()[0m

File [0;32mpandas/_libs/hashtable_class_helper.pxi:7081[0m, in [0;36mpandas._libs.hashtable.PyObjectHashTable.get_item[0;34m()[0m

File [0;32mpandas/_libs/hashtable_class_helper.pxi:7089[0m, in [0;36mpandas._libs.hashtable.PyObjectHashTable.get_item[0;34m()[0m

[0;31mKeyError[0m: 'text_file'

The above exception was the direct cause of the following exception:

[0;31mKeyError[0m                                  Traceback (most recent call last)
Cell [0;32mIn[4], line 10[0m
[1;32m      1[0m df [38;5;241m=[39m pd[38;5;241m.[39mread_csv(
[1;32m      2[0m     [38;5;124m"[39m[38;5;124mhttps://github.com/GLAM-Workbench/trove-parliamentary-papers-data/raw/main/trove-parliamentary-papers.csv[39m[38;5;124m"[39m,
[1;32m      3[0m     keep_default_na[38;5;241m=[39m[38;5;28;01mFalse[39;00m,
[1;32m      4[0m )
[1;32m      6[0m stats [38;5;241m=[39m [
[1;32m      7[0m     [[38;5;124m"[39m[38;5;124mNumber of digitised Parliamentary Papers[39m[38;5;124m"[39m, df[38;5;241m.[39mshape[[38;5;241m0[39m]],
[1;32m      8[0m     [
[1;32m      9[0m         [38;5;124m"[39m[38;5;124mNumber of Parliamentary Papers with OCRd text[39m[38;5;124m"[39m,
[0;32m---> 10[0m         df[38;5;241m.[39mloc[[43mdf[49m[43m[[49m[38;5;124;43m"[39;49m[38;5;124;43mtext_file[39;49m[38;5;124;43m"[39;49m[43m][49m[38;5;241m.[39mnotnull()][38;5;241m.[39mshape[[38;5;241m0[39m],
[1;32m     11[0m     ],
[1;32m     12[0m     [[38;5;124m"[39m[38;5;124mTotal number of pages[39m[38;5;124m"[39m, df[[38;5;124m"[39m[38;5;124mpages[39m[38;5;124m"[39m][38;5;241m.[39msum()],
[1;32m     13[0m     [[38;5;124m"[39m[38;5;124mMedian number of pages per publication[39m[38;5;124m"[39m, df[[38;5;124m"[39m[38;5;124mpages[39m[38;5;124m"[39m][38;5;241m.[39mmedian()],
[1;32m     14[0m ]
[1;32m     16[0m stats_df [38;5;241m=[39m pd[38;5;241m.[39mDataFrame(stats)
[1;32m     17[0m stats_df[38;5;241m.[39mstyle[38;5;241m.[39mformat(thousands[38;5;241m=[39m[38;5;124m"[39m[38;5;124m,[39m[38;5;124m"[39m, precision[38;5;241m=[39m[38;5;241m0[39m)[38;5;241m.[39mhide()[38;5;241m.[39mhide(axis[38;5;241m=[39m[38;5;241m1[39m)[38;5;241m.[39mset_properties(
[1;32m     18[0m     [38;5;241m*[39m[38;5;241m*[39m{[38;5;124m"[39m[38;5;124mtext-align[39m[38;5;124m"[39m: [38;5;124m"[39m[38;5;124mleft[39m[38;5;124m"[39m}
[1;32m     19[0m )

File [0;32m/opt/hostedtoolcache/Python/3.10.13/x64/lib/python3.10/site-packages/pandas/core/frame.py:4090[0m, in [0;36mDataFrame.__getitem__[0;34m(self, key)[0m
[1;32m   4088[0m [38;5;28;01mif[39;00m [38;5;28mself[39m[38;5;241m.[39mcolumns[38;5;241m.[39mnlevels [38;5;241m>[39m [38;5;241m1[39m:
[1;32m   4089[0m     [38;5;28;01mreturn[39;00m [38;5;28mself[39m[38;5;241m.[39m_getitem_multilevel(key)
[0;32m-> 4090[0m indexer [38;5;241m=[39m [38;5;28;43mself[39;49m[38;5;241;43m.[39;49m[43mcolumns[49m[38;5;241;43m.[39;49m[43mget_loc[49m[43m([49m[43mkey[49m[43m)[49m
[1;32m   4091[0m [38;5;28;01mif[39;00m is_integer(indexer):
[1;32m   4092[0m     indexer [38;5;241m=[39m [indexer]

File [0;32m/opt/hostedtoolcache/Python/3.10.13/x64/lib/python3.10/site-packages/pandas/core/indexes/base.py:3812[0m, in [0;36mIndex.get_loc[0;34m(self, key)[0m
[1;32m   3807[0m     [38;5;28;01mif[39;00m [38;5;28misinstance[39m(casted_key, [38;5;28mslice[39m) [38;5;129;01mor[39;00m (
[1;32m   3808[0m         [38;5;28misinstance[39m(casted_key, abc[38;5;241m.[39mIterable)
[1;32m   3809[0m         [38;5;129;01mand[39;00m [38;5;28many[39m([38;5;28misinstance[39m(x, [38;5;28mslice[39m) [38;5;28;01mfor[39;00m x [38;5;129;01min[39;00m casted_key)
[1;32m   3810[0m     ):
[1;32m   3811[0m         [38;5;28;01mraise[39;00m InvalidIndexError(key)
[0;32m-> 3812[0m     [38;5;28;01mraise[39;00m [38;5;167;01mKeyError[39;00m(key) [38;5;28;01mfrom[39;00m [38;5;21;01merr[39;00m
[1;32m   3813[0m [38;5;28;01mexcept[39;00m [38;5;167;01mTypeError[39;00m:
[1;32m   3814[0m     [38;5;66;03m# If we have a listlike key, _check_indexing_error will raise[39;00m
[1;32m   3815[0m     [38;5;66;03m#  InvalidIndexError. Otherwise we fall through and re-raise[39;00m
[1;32m   3816[0m     [38;5;66;03m#  the TypeError.[39;00m
[1;32m   3817[0m     [38;5;28mself[39m[38;5;241m.[39m_check_indexing_error(key)

[0;31mKeyError[0m: 'text_file'

